Workbook

Sheet 0_Overview
A1: Car Price Analysis
A3: Project Summary
A5: Raw rows | B5: =COUNTA('1_Raw_Data'!A:A)-1 -> 2500
A6: Clean rows | B6: =COUNTA('2_Clean_Data'!A:A)-1 -> 2500
A7: Distinct Sale IDs | B7: =SUM('2_Clean_Data'!R2:R2501) -> 598
A8: Average Selling Price | B8: =AVERAGE('2_Clean_Data'!E2:E2501) -> 13359.012
A9: Average Price Difference | B9: =AVERAGE('2_Clean_Data'!G2:G2501) -> 4018.1876
A10: Rows with Duplicate Sale IDs | B10: =COUNTIF('2_Clean_Data'!P2:P2501,"Duplicate ID") -> 2462
A13: What this workbook demonstrates
A14: • Raw data is preserved for transparency, while headers and layout are cleaned for readability.
A15: • Clean_Data standardizes text, dates, numbers, regions, colors, and owner values.
A16: • Duplicate Sale IDs are flagged instead of deleted, so no transaction rows are lost.
A17: • Summary tables and charts are linked directly to the cleaned dataset.
A20: Key cleaning rules
A21: • 7 car model names standardized.
A22: • Fuel Type, Transmission, Seller Type, Region, and Color normalized.
A23: • Currency and km text removed from numeric fields.
A24: • Outliers and duplicate Sale IDs flagged with formulas.

Sheet 1_Raw_Data
A1: Sale_Id | B1: Sale_Date | C1: Car_Model | D1: Year | E1: Selling_Price | F1: Present_Price | G1: Km_Driven | H1: Fuel_Type | I1: Transmission | J1: Seller_Type | K1: Region | L1: Color | M1: Owner
A2: 1104 | B2: 2021-10-13 | C2: Honda Civic | D2: 2014 | E2: 15172 | F2: 18000 | G2: 25000 km | H2: Electric | I2: Manual | J2: Dealer | K2: EU | L2: white | M2: 1
A3: 1429 | B3: 2024-01-22 | C3: Toyota Corolla | D3: 2022 | E3: 8677 | F3: 15000 | G3: 120000 | H3: Petrol | I3: manual | J3: private | K3: asia | L3: Silver | M3: 1
A4: 1367 | B4: 2021-07-18 | C4: focus | D4: 2019 | E4: 4888 | F4: 9000 | G4: 15000 | J4: Dealer | K4: South America | L4: black
A5: 1046 | B5: 2021-05-23 | C5: Audi A4 | D5: 2018 | E5: 19425 | F5: 22000 | G5: 80000 | H5: diesel | I5: Manual | J5: private | K5: Asia | L5: blue | M5: 2
A6: 1073 | B6: 2022-07-01 | C6: Ford Focus | D6: 2019 | E6: 15510 | F6: 22000 | G6: 25000 | H6: Diesel | I6: automatic | J6: private | K6: Asia | M6: 1
A7: 1274 | B7: 2023-04-02 | C7: audi a4 | D7: 2014 | E7: $11416 | F7: 15000 | G7: 15000 | H7: hybrid | I7: manual | J7: private | K7: South America | L7: blue | M7: 1
A8: 1269 | B8: 2024-01-09 | C8: bmw 3 series | D8: 2016 | E8: 9402 | F8: 15000 | G8: 120000 | H8: hybrid | I8: manual | J8: dealer | L8: blue | M8: 0
A9: 1065 | B9: 2023-05-15 | C9: toyota corolla | D9: 2015 | E9: 9690 | F9: 12000 | G9: 120000 | H9: Hybrid | J9: Dealer | K9: EU | M9: 2
A10: 1003 | B10: 2023-07-19 | C10: audi a4 | D10: 2015 | E10: 15705 | F10: 18000 | G10: 60000 | H10: Diesel | J10: Dealer | K10: Asia
A11: 1000 | B11: 2023-12-23 | C11: focus | D11: 2016 | E11: 16582 | F11: 22000 | G11: 25000 km | H11: hybrid | I11: Automatic | J11: dealer | K11: Europe | L11: white
A12: 1131 | B12: 2021-09-15 | C12: Corolla | D12: 2015 | E12: 25637 | F12: 31000 | G12: 15000 km | H12: Electric | I12: manual | K12: north america | L12: Silver | M12: 3
A13: 1065 | B13: 2022-04-06 | C13: Volkswagen Golf | D13: 2021 | E13: 27970 | F13: 31000 | G13: 15000 km | H13: diesel | I13: Manual | J13: Dealer | K13: Europe | L13: white | M13: 0
A14: 1497 | B14: 2022-07-25 | C14: toyota corolla | D14: 2019 | E14: 6051 | F14: 9000 usd | G14: 80000 | I14: manual | J14: private | K14: South America | L14: white | M14: 0
A15: 1478 | B15: 2023-04-22 | C15: Honda Civic | D15: 2018 | E15: 21531 | F15: 26000 usd | G15: 40000 | H15: petrol | I15: Manual | J15: private | K15: asia | L15: black | M15: 1
A16: 1285 | B16: 2022-01-11 | C16: focus | D16: 2017 | E16: 26544 | F16: 31000 | G16: 25000 km | H16: petrol | I16: Manual | K16: Europe | L16: black | M16: 1
A17: 1060 | B17: 2023-04-02 | C17: Ford Focus | D17: 2020 | E17: $28249 | F17: 31000 usd | G17: 60000 | I17: Automatic | J17: private | L17: blue | M17: 1
A18: 1062 | B18: 2024-01-16 | C18: focus | D18: 2018 | E18: 9256 | F18: 15000 usd | G18: 15000 | H18: Diesel | I18: Manual | K18: EU | L18: White | M18: 0
A19: 1252 | B19: 2024-03-12 | C19: Corolla | D19: 2018 | E19: 13018 | F19: 15000 usd | G19: 60000 km | H19: hybrid | I19: Automatic | J19: dealer | K19: asia | L19: white | M19: 2
A20: 1009 | B20: 2021-05-29 | C20: golf | D20: 2016 | E20: 14410 | F20: 18000 | G20: 60000 | H20: petrol | J20: dealer | L20: Silver | M20: 1
A21: 1448 | B21: 2021-11-20 | C21: Volkswagen Golf | D21: 2015 | E21: 11666 | F21: 15000 | G21: 40000 | H21: Petrol | J21: Private | K21: EU | L21: White | M21: 2
A22: 1351 | B22: 2022-03-08 | C22: Honda Civic | D22: 2015 | E22: 8692 | F22: 12000 | G22: 40000 | I22: Automatic | J22: Dealer | K22: EU | L22: Blue | M22: 2
A23: 1165 | B23: 2022-06-21 | C23: toyota corolla | D23: 2014 | E23: 15781 | F23: 22000 | G23: 25000 | H23: Petrol | I23: Manual | J23: Dealer | K23: North America | M23: 0
A24: 1315 | B24: 2021-03-27 | C24: Volkswagen Golf | E24: 9956 | F24: 12000 | G24: 60000 | H24: Petrol | I24: Automatic | J24: dealer | K24: north america | L24: black | M24: 2
A25: 1422 | B25: 2021-12-29 | C25: Mercedes C Class | E25: $9669 | F25: 12000 | G25: 25000 | H25: Electric | I25: manual | J25: Private | K25: North America | L25: black | M25: 3
A26: 1312 | B26: 2022-12-18 | C26: toyota corolla | D26: 2021 | E26: 10230 | F26: 15000 | G26: 25000 km | H26: diesel | I26: automatic | J26: Private | K26: Asia | L26: black | M26: 2
A27: 1028 | B27: 2022-11-10 | C27: Volkswagen Golf | D27: 2018 | E27: $20608 | F27: 26000 | G27: 120000 km | H27: Hybrid | I27: Manual | J27: Dealer | K27: South America | L27: silver | M27: 2
A28: 1260 | B28: 2022-01-25 | C28: Mercedes C Class | E28: $3277 | F28: 9000 | G28: 60000 | H28: diesel | I28: Automatic | J28: private | K28: EU | L28: silver
A29: 1316 | B29: 2023-11-05 | C29: audi a4 | D29: 2018 | E29: 5540 | F29: 9000 | G29: 120000 | H29: Diesel | I29: manual | J29: private | K29: South America | L29: White
A30: 1440 | B30: 2022-03-07 | C30: Audi A4 | D30: 2020 | E30: 3650 | F30: 7000 | G30: 40000 | I30: automatic | J30: dealer | L30: blue | M30: 1
A31: 1230 | B31: 2022-09-28 | C31: Corolla | D31: 2018 | E31: 19076 | F31: 22000 usd | G31: 15000 km | J31: Dealer | K31: SA | L31: Blue
A32: 1005 | B32: 2021-10-30 | C32: focus | D32: 2020 | E32: 28002 | F32: 31000 | G32: 60000 | H32: Electric | I32: manual | J32: dealer | L32: blue | M32: 0
A33: 1572 | B33: 2023-12-24 | C33: BMW 3 Series | D33: 2015 | E33: 26194 | F33: 31000 | G33: 25000 | H33: Electric | J33: private | K33: North America | L33: blue | M33: 3
A34: 1281 | B34: 2022-05-05 | C34: bmw 3 series | D34: 2017 | E34: 13031 | F34: 18000 | G34: 80000 km | H34: hybrid | I34: Automatic | K34: EU | L34: White | M34: 1
A35: 1424 | B35: 2021-05-12 | C35: BMW 3 Series | D35: 2020 | E35: 9248 | F35: 12000 | G35: 120000 | H35: diesel | I35: automatic | J35: private | K35: Europe | L35: Blue | M35: 3
A36: 1559 | B36: 2024-01-08 | C36: Toyota Corolla | D36: 2019 | E36: 13568 | F36: 18000 | G36: 60000 | H36: Hybrid | I36: automatic | J36: private | K36: Europe | L36: Blue | M36: 2
A37: 1027 | B37: 2023-12-30 | C37: golf | D37: 2016 | E37: 24903 | F37: 31000 | G37: 25000 | H37: petrol | I37: automatic | J37: dealer | K37: SA | L37: White | M37: 0
A38: 1345 | B38: 2022-11-01 | C38: bmw 3 series | D38: 2020 | E38: 17276 | F38: 22000 | G38: 25000 | H38: Electric | I38: Automatic | J38: Dealer | K38: SA | L38: Black
A39: 1031 | B39: 2021-03-24 | C39: toyota corolla | D39: 2019 | E39: 13438 | F39: 15000 | G39: 120000 km | H39: Diesel | I39: manual | J39: dealer | K39: SA | L39: black
A40: 1167 | B40: 2021-08-23 | C40: focus | D40: 2021 | E40: 15626 | F40: 18000 usd | G40: 40000 km | H40: Hybrid | J40: private | K40: South America | L40: white | M40: 0
...

Sheet 2_Clean_Data
A1: Sale_Id | B1: Sale_Date | C1: Car_Model | D1: Year | E1: Selling_Price | F1: Present_Price | G1: Price_Difference | H1: Km_Driven | I1: Fuel_Type | J1: Transmission | K1: Seller_Type | L1: Region | M1: Color | N1: Owner | O1: Outlier_Flag | P1: Duplicate_Sale_ID_Flag | Q1: Price_Range | R1: Unique_Sale_ID_Flag
A2: 1104 | B2: 44482 | C2: Honda Civic | D2: 2014 | E2: 15172 | F2: 18000 | G2: =IF(OR(F2="",E2=""),"",F2-E2) -> 2828 | H2: 25000 | I2: Electric | J2: Manual | K2: Dealer | L2: Europe | M2: White | N2: 1 | O2: =IF(E2<1000,"Outlier","Normal") -> Normal | P2: =IF(COUNTIF($A$2:$A$2501,A2)>1,"Duplicate ID","Unique ID") -> Duplicate ID | Q2: =IF(E2<5000,"0-4,999",IF(E2<10000,"5,000-9,999",IF(E2<15000,"10,000-14,999",IF(E2<20000,"15,000-19,999",IF(E2<25000,"20,000-24,999","25,000-30,000"))))) -> 15,000-19,999 | R2: =IF(COUNTIF($A$2:A2,A2)=1,1,0) -> 1
A3: 1429 | B3: 45313 | C3: Toyota Corolla | D3: 2022 | E3: 8677 | F3: 15000 | G3: =IF(OR(F3="",E3=""),"",F3-E3) -> 6323 | H3: 120000 | I3: Petrol | J3: Manual | K3: Private | L3: Asia | M3: Silver | N3: 1 | O3: =IF(E3<1000,"Outlier","Normal") -> Normal | P3: =IF(COUNTIF($A$2:$A$2501,A3)>1,"Duplicate ID","Unique ID") -> Duplicate ID | Q3: =IF(E3<5000,"0-4,999",IF(E3<10000,"5,000-9,999",IF(E3<15000,"10,000-14,999",IF(E3<20000,"15,000-19,999",IF(E3<25000,"20,000-24,999","25,000-30,000"))))) -> 5,000-9,999 | R3: =IF(COUNTIF($A$2:A3,A3)=1,1,0) -> 1
A4: 1367 | B4: 44395 | C4: Ford Focus | D4: 2019 | E4: 4888 | F4: 9000 | G4: =IF(OR(F4="",E4=""),"",F4-E4) -> 4112 | H4: 15000 | I4: Unknown | J4: Unknown | K4: Dealer | L4: South America | M4: Black | N4: Unknown | O4: =IF(E4<1000,"Outlier","Normal") -> Normal | P4: =IF(COUNTIF($A$2:$A$2501,A4)>1,"Duplicate ID","Unique ID") -> Duplicate ID | Q4: =IF(E4<5000,"0-4,999",IF(E4<10000,"5,000-9,999",IF(E4<15000,"10,000-14,999",IF(E4<20000,"15,000-19,999",IF(E4<25000,"20,000-24,999","25,000-30,000"))))) -> 0-4,999 | R4: =IF(COUNTIF($A$2:A4,A4)=1,1,0) -> 1
A5: 1046 | B5: 44339 | C5: Audi A4 | D5: 2018 | E5: 19425 | F5: 22000 | G5: =IF(OR(F5="",E5=""),"",F5-E5) -> 2575 | H5: 80000 | I5: Diesel | J5: Manual | K5: Private | L5: Asia | M5: Blue | N5: 2 | O5: =IF(E5<1000,"Outlier","Normal") -> Normal | P5: =IF(COUNTIF($A$2:$A$2501,A5)>1,"Duplicate ID","Unique ID") -> Duplicate ID | Q5: =IF(E5<5000,"0-4,999",IF(E5<10000,"5,000-9,999",IF(E5<15000,"10,000-14,999",IF(E5<20000,"15,000-19,999",IF(E5<25000,"20,000-24,999","25,000-30,000"))))) -> 15,000-19,999 | R5: =IF(COUNTIF($A$2:A5,A5)=1,1,0) -> 1
A6: 1073 | B6: 44743 | C6: Ford Focus | D6: 2019 | E6: 15510 | F6: 22000 | G6: =IF(OR(F6="",E6=""),"",F6-E6) -> 6490 | H6: 25000 | I6: Diesel | J6: Automatic | K6: Private | L6: Asia | M6: Unknown | N6: 1 | O6: =IF(E6<1000,"Outlier","Normal") -> Normal | P6: =IF(COUNTIF($A$2:$A$2501,A6)>1,"Duplicate ID","Unique ID") -> Duplicate ID | Q6: =IF(E6<5000,"0-4,999",IF(E6<10000,"5,000-9,999",IF(E6<15000,"10,000-14,999",IF(E6<20000,"15,000-19,999",IF(E6<25000,"20,000-24,999","25,000-30,000"))))) -> 15,000-19,999 | R6: =IF(COUNTIF($A$2:A6,A6)=1,1,0) -> 1
A7: 1274 | B7: 45018 | C7: Audi A4 | D7: 2014 | E7: 11416 | F7: 15000 | G7: =IF(OR(F7="",E7=""),"",F7-E7) -> 3584 | H7: 15000 | I7: Hybrid | J7: Manual | K7: Private | L7: South America | M7: Blue | N7: 1 | O7: =IF(E7<1000,"Outlier","Normal") -> Normal | P7: =IF(COUNTIF($A$2:$A$2501,A7)>1,"Duplicate ID","Unique ID") -> Duplicate ID | Q7: =IF(E7<5000,"0-4,999",IF(E7<10000,"5,000-9,999",IF(E7<15000,"10,000-14,999",IF(E7<20000,"15,000-19,999",IF(E7<25000,"20,000-24,999","25,000-30,000"))))) -> 10,000-14,999 | R7: =IF(COUNTIF($A$2:A7,A7)=1,1,0) -> 1
A8: 1269 | B8: 45300 | C8: BMW 3 Series | D8: 2016 | E8: 9402 | F8: 15000 | G8: =IF(OR(F8="",E8=""),"",F8-E8) -> 5598 | H8: 120000 | I8: Hybrid | J8: Manual | K8: Dealer | L8: Unknown | M8: Blue | N8: 0 | O8: =IF(E8<1000,"Outlier","Normal") -> Normal | P8: =IF(COUNTIF($A$2:$A$2501,A8)>1,"Duplicate ID","Unique ID") -> Duplicate ID | Q8: =IF(E8<5000,"0-4,999",IF(E8<10000,"5,000-9,999",IF(E8<15000,"10,000-14,999",IF(E8<20000,"15,000-19,999",IF(E8<25000,"20,000-24,999","25,000-30,000"))))) -> 5,000-9,999 | R8: =IF(COUNTIF($A$2:A8,A8)=1,1,0) -> 1
A9: 1065 | B9: 45061 | C9: Toyota Corolla | D9: 2015 | E9: 9690 | F9: 12000 | G9: =IF(OR(F9="",E9=""),"",F9-E9) -> 2310 | H9: 120000 | I9: Hybrid | J9: Unknown | K9: Dealer | L9: Europe | M9: Unknown | N9: 2 | O9: =IF(E9<1000,"Outlier","Normal") -> Normal | P9: =IF(COUNTIF($A$2:$A$2501,A9)>1,"Duplicate ID","Unique ID") -> Duplicate ID | Q9: =IF(E9<5000,"0-4,999",IF(E9<10000,"5,000-9,999",IF(E9<15000,"10,000-14,999",IF(E9<20000,"15,000-19,999",IF(E9<25000,"20,000-24,999","25,000-30,000"))))) -> 5,000-9,999 | R9: =IF(COUNTIF($A$2:A9,A9)=1,1,0) -> 1
A10: 1003 | B10: 45126 | C10: Audi A4 | D10: 2015 | E10: 15705 | F10: 18000 | G10: =IF(OR(F10="",E10=""),"",F10-E10) -> 2295 | H10: 60000 | I10: Diesel | J10: Unknown | K10: Dealer | L10: Asia | M10: Unknown | N10: Unknown | O10: =IF(E10<1000,"Outlier","Normal") -> Normal | P10: =IF(COUNTIF($A$2:$A$2501,A10)>1,"Duplicate ID","Unique ID") -> Duplicate ID | Q10: =IF(E10<5000,"0-4,999",IF(E10<10000,"5,000-9,999",IF(E10<15000,"10,000-14,999",IF(E10<20000,"15,000-19,999",IF(E10<25000,"20,000-24,999","25,000-30,000"))))) -> 15,000-19,999 | R10: =IF(COUNTIF($A$2:A10,A10)=1,1,0) -> 1
A11: 1000 | B11: 45283 | C11: Ford Focus | D11: 2016 | E11: 16582 | F11: 22000 | G11: =IF(OR(F11="",E11=""),"",F11-E11) -> 5418 | H11: 25000 | I11: Hybrid | J11: Automatic | K11: Dealer | L11: Europe | M11: White | N11: Unknown | O11: =IF(E11<1000,"Outlier","Normal") -> Normal | P11: =IF(COUNTIF($A$2:$A$2501,A11)>1,"Duplicate ID","Unique ID") -> Duplicate ID | Q11: =IF(E11<5000,"0-4,999",IF(E11<10000,"5,000-9,999",IF(E11<15000,"10,000-14,999",IF(E11<20000,"15,000-19,999",IF(E11<25000,"20,000-24,999","25,000-30,000"))))) -> 15,000-19,999 | R11: =IF(COUNTIF($A$2:A11,A11)=1,1,0) -> 1
A12: 1131 | B12: 44454 | C12: Toyota Corolla | D12: 2015 | E12: 25637 | F12: 31000 | G12: =IF(OR(F12="",E12=""),"",F12-E12) -> 5363 | H12: 15000 | I12: Electric | J12: Manual | K12: Unknown | L12: North America | M12: Silver | N12: 3 | O12: =IF(E12<1000,"Outlier","Normal") -> Normal | P12: =IF(COUNTIF($A$2:$A$2501,A12)>1,"Duplicate ID","Unique ID") -> Duplicate ID | Q12: =IF(E12<5000,"0-4,999",IF(E12<10000,"5,000-9,999",IF(E12<15000,"10,000-14,999",IF(E12<20000,"15,000-19,999",IF(E12<25000,"20,000-24,999","25,000-30,000"))))) -> 25,000-30,000 | R12: =IF(COUNTIF($A$2:A12,A12)=1,1,0) -> 1
A13: 1065 | B13: 44657 | C13: Volkswagen Golf | D13: 2021 | E13: 27970 | F13: 31000 | G13: =IF(OR(F13="",E13=""),"",F13-E13) -> 3030 | H13: 15000 | I13: Diesel | J13: Manual | K13: Dealer | L13: Europe | M13: White | N13: 0 | O13: =IF(E13<1000,"Outlier","Normal") -> Normal | P13: =IF(COUNTIF($A$2:$A$2501,A13)>1,"Duplicate ID","Unique ID") -> Duplicate ID | Q13: =IF(E13<5000,"0-4,999",IF(E13<10000,"5,000-9,999",IF(E13<15000,"10,000-14,999",IF(E13<20000,"15,000-19,999",IF(E13<25000,"20,000-24,999","25,000-30,000"))))) -> 25,000-30,000 | R13: =IF(COUNTIF($A$2:A13,A13)=1,1,0) -> 0
A14: 1497 | B14: 44767 | C14: Toyota Corolla | D14: 2019 | E14: 6051 | F14: 9000 | G14: =IF(OR(F14="",E14=""),"",F14-E14) -> 2949 | H14: 80000 | I14: Unknown | J14: Manual | K14: Private | L14: South America | M14: White | N14: 0 | O14: =IF(E14<1000,"Outlier","Normal") -> Normal | P14: =IF(COUNTIF($A$2:$A$2501,A14)>1,"Duplicate ID","Unique ID") -> Duplicate ID | Q14: =IF(E14<5000,"0-4,999",IF(E14<10000,"5,000-9,999",IF(E14<15000,"10,000-14,999",IF(E14<20000,"15,000-19,999",IF(E14<25000,"20,000-24,999","25,000-30,000"))))) -> 5,000-9,999 | R14: =IF(COUNTIF($A$2:A14,A14)=1,1,0) -> 1
A15: 1478 | B15: 45038 | C15: Honda Civic | D15: 2018 | E15: 21531 | F15: 26000 | G15: =IF(OR(F15="",E15=""),"",F15-E15) -> 4469 | H15: 40000 | I15: Petrol | J15: Manual | K15: Private | L15: Asia | M15: Black | N15: 1 | O15: =IF(E15<1000,"Outlier","Normal") -> Normal | P15: =IF(COUNTIF($A$2:$A$2501,A15)>1,"Duplicate ID","Unique ID") -> Duplicate ID | Q15: =IF(E15<5000,"0-4,999",IF(E15<10000,"5,000-9,999",IF(E15<15000,"10,000-14,999",IF(E15<20000,"15,000-19,999",IF(E15<25000,"20,000-24,999","25,000-30,000"))))) -> 20,000-24,999 | R15: =IF(COUNTIF($A$2:A15,A15)=1,1,0) -> 1
A16: 1285 | B16: 44572 | C16: Ford Focus | D16: 2017 | E16: 26544 | F16: 31000 | G16: =IF(OR(F16="",E16=""),"",F16-E16) -> 4456 | H16: 25000 | I16: Petrol | J16: Manual | K16: Unknown | L16: Europe | M16: Black | N16: 1 | O16: =IF(E16<1000,"Outlier","Normal") -> Normal | P16: =IF(COUNTIF($A$2:$A$2501,A16)>1,"Duplicate ID","Unique ID") -> Duplicate ID | Q16: =IF(E16<5000,"0-4,999",IF(E16<10000,"5,000-9,999",IF(E16<15000,"10,000-14,999",IF(E16<20000,"15,000-19,999",IF(E16<25000,"20,000-24,999","25,000-30,000"))))) -> 25,000-30,000 | R16: =IF(COUNTIF($A$2:A16,A16)=1,1,0) -> 1
A17: 1060 | B17: 45018 | C17: Ford Focus | D17: 2020 | E17: 28249 | F17: 31000 | G17: =IF(OR(F17="",E17=""),"",F17-E17) -> 2751 | H17: 60000 | I17: Unknown | J17: Automatic | K17: Private | L17: Unknown | M17: Blue | N17: 1 | O17: =IF(E17<1000,"Outlier","Normal") -> Normal | P17: =IF(COUNTIF($A$2:$A$2501,A17)>1,"Duplicate ID","Unique ID") -> Duplicate ID | Q17: =IF(E17<5000,"0-4,999",IF(E17<10000,"5,000-9,999",IF(E17<15000,"10,000-14,999",IF(E17<20000,"15,000-19,999",IF(E17<25000,"20,000-24,999","25,000-30,000"))))) -> 25,000-30,000 | R17: =IF(COUNTIF($A$2:A17,A17)=1,1,0) -> 1
A18: 1062 | B18: 45307 | C18: Ford Focus | D18: 2018 | E18: 9256 | F18: 15000 | G18: =IF(OR(F18="",E18=""),"",F18-E18) -> 5744 | H18: 15000 | I18: Diesel | J18: Manual | K18: Unknown | L18: Europe | M18: White | N18: 0 | O18: =IF(E18<1000,"Outlier","Normal") -> Normal | P18: =IF(COUNTIF($A$2:$A$2501,A18)>1,"Duplicate ID","Unique ID") -> Duplicate ID | Q18: =IF(E18<5000,"0-4,999",IF(E18<10000,"5,000-9,999",IF(E18<15000,"10,000-14,999",IF(E18<20000,"15,000-19,999",IF(E18<25000,"20,000-24,999","25,000-30,000"))))) -> 5,000-9,999 | R18: =IF(COUNTIF($A$2:A18,A18)=1,1,0) -> 1
A19: 1252 | B19: 45363 | C19: Toyota Corolla | D19: 2018 | E19: 13018 | F19: 15000 | G19: =IF(OR(F19="",E19=""),"",F19-E19) -> 1982 | H19: 60000 | I19: Hybrid | J19: Automatic | K19: Dealer | L19: Asia | M19: White | N19: 2 | O19: =IF(E19<1000,"Outlier","Normal") -> Normal | P19: =IF(COUNTIF($A$2:$A$2501,A19)>1,"Duplicate ID","Unique ID") -> Duplicate ID | Q19: =IF(E19<5000,"0-4,999",IF(E19<10000,"5,000-9,999",IF(E19<15000,"10,000-14,999",IF(E19<20000,"15,000-19,999",IF(E19<25000,"20,000-24,999","25,000-30,000"))))) -> 10,000-14,999 | R19: =IF(COUNTIF($A$2:A19,A19)=1,1,0) -> 1
A20: 1009 | B20: 44345 | C20: Volkswagen Golf | D20: 2016 | E20: 14410 | F20: 18000 | G20: =IF(OR(F20="",E20=""),"",F20-E20) -> 3590 | H20: 60000 | I20: Petrol | J20: Unknown | K20: Dealer | L20: Unknown | M20: Silver | N20: 1 | O20: =IF(E20<1000,"Outlier","Normal") -> Normal | P20: =IF(COUNTIF($A$2:$A$2501,A20)>1,"Duplicate ID","Unique ID") -> Duplicate ID | Q20: =IF(E20<5000,"0-4,999",IF(E20<10000,"5,000-9,999",IF(E20<15000,"10,000-14,999",IF(E20<20000,"15,000-19,999",IF(E20<25000,"20,000-24,999","25,000-30,000"))))) -> 10,000-14,999 | R20: =IF(COUNTIF($A$2:A20,A20)=1,1,0) -> 1
A21: 1448 | B21: 44520 | C21: Volkswagen Golf | D21: 2015 | E21: 11666 | F21: 15000 | G21: =IF(OR(F21="",E21=""),"",F21-E21) -> 3334 | H21: 40000 | I21: Petrol | J21: Unknown | K21: Private | L21: Europe | M21: White | N21: 2 | O21: =IF(E21<1000,"Outlier","Normal") -> Normal | P21: =IF(COUNTIF($A$2:$A$2501,A21)>1,"Duplicate ID","Unique ID") -> Duplicate ID | Q21: =IF(E21<5000,"0-4,999",IF(E21<10000,"5,000-9,999",IF(E21<15000,"10,000-14,999",IF(E21<20000,"15,000-19,999",IF(E21<25000,"20,000-24,999","25,000-30,000"))))) -> 10,000-14,999 | R21: =IF(COUNTIF($A$2:A21,A21)=1,1,0) -> 1
A22: 1351 | B22: 44628 | C22: Honda Civic | D22: 2015 | E22: 8692 | F22: 12000 | G22: =IF(OR(F22="",E22=""),"",F22-E22) -> 3308 | H22: 40000 | I22: Unknown | J22: Automatic | K22: Dealer | L22: Europe | M22: Blue | N22: 2 | O22: =IF(E22<1000,"Outlier","Normal") -> Normal | P22: =IF(COUNTIF($A$2:$A$2501,A22)>1,"Duplicate ID","Unique ID") -> Duplicate ID | Q22: =IF(E22<5000,"0-4,999",IF(E22<10000,"5,000-9,999",IF(E22<15000,"10,000-14,999",IF(E22<20000,"15,000-19,999",IF(E22<25000,"20,000-24,999","25,000-30,000"))))) -> 5,000-9,999 | R22: =IF(COUNTIF($A$2:A22,A22)=1,1,0) -> 1
A23: 1165 | B23: 44733 | C23: Toyota Corolla | D23: 2014 | E23: 15781 | F23: 22000 | G23: =IF(OR(F23="",E23=""),"",F23-E23) -> 6219 | H23: 25000 | I23: Petrol | J23: Manual | K23: Dealer | L23: North America | M23: Unknown | N23: 0 | O23: =IF(E23<1000,"Outlier","Normal") -> Normal | P23: =IF(COUNTIF($A$2:$A$2501,A23)>1,"Duplicate ID","Unique ID") -> Duplicate ID | Q23: =IF(E23<5000,"0-4,999",IF(E23<10000,"5,000-9,999",IF(E23<15000,"10,000-14,999",IF(E23<20000,"15,000-19,999",IF(E23<25000,"20,000-24,999","25,000-30,000"))))) -> 15,000-19,999 | R23: =IF(COUNTIF($A$2:A23,A23)=1,1,0) -> 1
A24: 1315 | B24: 44282 | C24: Volkswagen Golf | E24: 9956 | F24: 12000 | G24: =IF(OR(F24="",E24=""),"",F24-E24) -> 2044 | H24: 60000 | I24: Petrol | J24: Automatic | K24: Dealer | L24: North America | M24: Black | N24: 2 | O24: =IF(E24<1000,"Outlier","Normal") -> Normal | P24: =IF(COUNTIF($A$2:$A$2501,A24)>1,"Duplicate ID","Unique ID") -> Duplicate ID | Q24: =IF(E24<5000,"0-4,999",IF(E24<10000,"5,000-9,999",IF(E24<15000,"10,000-14,999",IF(E24<20000,"15,000-19,999",IF(E24<25000,"20,000-24,999","25,000-30,000"))))) -> 5,000-9,999 | R24: =IF(COUNTIF($A$2:A24,A24)=1,1,0) -> 1
A25: 1422 | B25: 44559 | C25: Mercedes C-Class | E25: 9669 | F25: 12000 | G25: =IF(OR(F25="",E25=""),"",F25-E25) -> 2331 | H25: 25000 | I25: Electric | J25: Manual | K25: Private | L25: North America | M25: Black | N25: 3 | O25: =IF(E25<1000,"Outlier","Normal") -> Normal | P25: =IF(COUNTIF($A$2:$A$2501,A25)>1,"Duplicate ID","Unique ID") -> Duplicate ID | Q25: =IF(E25<5000,"0-4,999",IF(E25<10000,"5,000-9,999",IF(E25<15000,"10,000-14,999",IF(E25<20000,"15,000-19,999",IF(E25<25000,"20,000-24,999","25,000-30,000"))))) -> 5,000-9,999 | R25: =IF(COUNTIF($A$2:A25,A25)=1,1,0) -> 1
A26: 1312 | B26: 44913 | C26: Toyota Corolla | D26: 2021 | E26: 10230 | F26: 15000 | G26: =IF(OR(F26="",E26=""),"",F26-E26) -> 4770 | H26: 25000 | I26: Diesel | J26: Automatic | K26: Private | L26: Asia | M26: Black | N26: 2 | O26: =IF(E26<1000,"Outlier","Normal") -> Normal | P26: =IF(COUNTIF($A$2:$A$2501,A26)>1,"Duplicate ID","Unique ID") -> Unique ID | Q26: =IF(E26<5000,"0-4,999",IF(E26<10000,"5,000-9,999",IF(E26<15000,"10,000-14,999",IF(E26<20000,"15,000-19,999",IF(E26<25000,"20,000-24,999","25,000-30,000"))))) -> 10,000-14,999 | R26: =IF(COUNTIF($A$2:A26,A26)=1,1,0) -> 1
A27: 1028 | B27: 44875 | C27: Volkswagen Golf | D27: 2018 | E27: 20608 | F27: 26000 | G27: =IF(OR(F27="",E27=""),"",F27-E27) -> 5392 | H27: 120000 | I27: Hybrid | J27: Manual | K27: Dealer | L27: South America | M27: Silver | N27: 2 | O27: =IF(E27<1000,"Outlier","Normal") -> Normal | P27: =IF(COUNTIF($A$2:$A$2501,A27)>1,"Duplicate ID","Unique ID") -> Duplicate ID | Q27: =IF(E27<5000,"0-4,999",IF(E27<10000,"5,000-9,999",IF(E27<15000,"10,000-14,999",IF(E27<20000,"15,000-19,999",IF(E27<25000,"20,000-24,999","25,000-30,000"))))) -> 20,000-24,999 | R27: =IF(COUNTIF($A$2:A27,A27)=1,1,0) -> 1
A28: 1260 | B28: 44586 | C28: Mercedes C-Class | E28: 3277 | F28: 9000 | G28: =IF(OR(F28="",E28=""),"",F28-E28) -> 5723 | H28: 60000 | I28: Diesel | J28: Automatic | K28: Private | L28: Europe | M28: Silver | N28: Unknown | O28: =IF(E28<1000,"Outlier","Normal") -> Normal | P28: =IF(COUNTIF($A$2:$A$2501,A28)>1,"Duplicate ID","Unique ID") -> Duplicate ID | Q28: =IF(E28<5000,"0-4,999",IF(E28<10000,"5,000-9,999",IF(E28<15000,"10,000-14,999",IF(E28<20000,"15,000-19,999",IF(E28<25000,"20,000-24,999","25,000-30,000"))))) -> 0-4,999 | R28: =IF(COUNTIF($A$2:A28,A28)=1,1,0) -> 1
A29: 1316 | B29: 45235 | C29: Audi A4 | D29: 2018 | E29: 5540 | F29: 9000 | G29: =IF(OR(F29="",E29=""),"",F29-E29) -> 3460 | H29: 120000 | I29: Diesel | J29: Manual | K29: Private | L29: South America | M29: White | N29: Unknown | O29: =IF(E29<1000,"Outlier","Normal") -> Normal | P29: =IF(COUNTIF($A$2:$A$2501,A29)>1,"Duplicate ID","Unique ID") -> Duplicate ID | Q29: =IF(E29<5000,"0-4,999",IF(E29<10000,"5,000-9,999",IF(E29<15000,"10,000-14,999",IF(E29<20000,"15,000-19,999",IF(E29<25000,"20,000-24,999","25,000-30,000"))))) -> 5,000-9,999 | R29: =IF(COUNTIF($A$2:A29,A29)=1,1,0) -> 1
A30: 1440 | B30: 44627 | C30: Audi A4 | D30: 2020 | E30: 3650 | F30: 7000 | G30: =IF(OR(F30="",E30=""),"",F30-E30) -> 3350 | H30: 40000 | I30: Unknown | J30: Automatic | K30: Dealer | L30: Unknown | M30: Blue | N30: 1 | O30: =IF(E30<1000,"Outlier","Normal") -> Normal | P30: =IF(COUNTIF($A$2:$A$2501,A30)>1,"Duplicate ID","Unique ID") -> Duplicate ID | Q30: =IF(E30<5000,"0-4,999",IF(E30<10000,"5,000-9,999",IF(E30<15000,"10,000-14,999",IF(E30<20000,"15,000-19,999",IF(E30<25000,"20,000-24,999","25,000-30,000"))))) -> 0-4,999 | R30: =IF(COUNTIF($A$2:A30,A30)=1,1,0) -> 1
A31: 1230 | B31: 44832 | C31: Toyota Corolla | D31: 2018 | E31: 19076 | F31: 22000 | G31: =IF(OR(F31="",E31=""),"",F31-E31) -> 2924 | H31: 15000 | I31: Unknown | J31: Unknown | K31: Dealer | L31: South America | M31: Blue | N31: Unknown | O31: =IF(E31<1000,"Outlier","Normal") -> Normal | P31: =IF(COUNTIF($A$2:$A$2501,A31)>1,"Duplicate ID","Unique ID") -> Duplicate ID | Q31: =IF(E31<5000,"0-4,999",IF(E31<10000,"5,000-9,999",IF(E31<15000,"10,000-14,999",IF(E31<20000,"15,000-19,999",IF(E31<25000,"20,000-24,999","25,000-30,000"))))) -> 15,000-19,999 | R31: =IF(COUNTIF($A$2:A31,A31)=1,1,0) -> 1
A32: 1005 | B32: 44499 | C32: Ford Focus | D32: 2020 | E32: 28002 | F32: 31000 | G32: =IF(OR(F32="",E32=""),"",F32-E32) -> 2998 | H32: 60000 | I32: Electric | J32: Manual | K32: Dealer | L32: Unknown | M32: Blue | N32: 0 | O32: =IF(E32<1000,"Outlier","Normal") -> Normal | P32: =IF(COUNTIF($A$2:$A$2501,A32)>1,"Duplicate ID","Unique ID") -> Duplicate ID | Q32: =IF(E32<5000,"0-4,999",IF(E32<10000,"5,000-9,999",IF(E32<15000,"10,000-14,999",IF(E32<20000,"15,000-19,999",IF(E32<25000,"20,000-24,999","25,000-30,000"))))) -> 25,000-30,000 | R32: =IF(COUNTIF($A$2:A32,A32)=1,1,0) -> 1
A33: 1572 | B33: 45284 | C33: BMW 3 Series | D33: 2015 | E33: 26194 | F33: 31000 | G33: =IF(OR(F33="",E33=""),"",F33-E33) -> 4806 | H33: 25000 | I33: Electric | J33: Unknown | K33: Private | L33: North America | M33: Blue | N33: 3 | O33: =IF(E33<1000,"Outlier","Normal") -> Normal | P33: =IF(COUNTIF($A$2:$A$2501,A33)>1,"Duplicate ID","Unique ID") -> Duplicate ID | Q33: =IF(E33<5000,"0-4,999",IF(E33<10000,"5,000-9,999",IF(E33<15000,"10,000-14,999",IF(E33<20000,"15,000-19,999",IF(E33<25000,"20,000-24,999","25,000-30,000"))))) -> 25,000-30,000 | R33: =IF(COUNTIF($A$2:A33,A33)=1,1,0) -> 1
A34: 1281 | B34: 44686 | C34: BMW 3 Series | D34: 2017 | E34: 13031 | F34: 18000 | G34: =IF(OR(F34="",E34=""),"",F34-E34) -> 4969 | H34: 80000 | I34: Hybrid | J34: Automatic | K34: Unknown | L34: Europe | M34: White | N34: 1 | O34: =IF(E34<1000,"Outlier","Normal") -> Normal | P34: =IF(COUNTIF($A$2:$A$2501,A34)>1,"Duplicate ID","Unique ID") -> Duplicate ID | Q34: =IF(E34<5000,"0-4,999",IF(E34<10000,"5,000-9,999",IF(E34<15000,"10,000-14,999",IF(E34<20000,"15,000-19,999",IF(E34<25000,"20,000-24,999","25,000-30,000"))))) -> 10,000-14,999 | R34: =IF(COUNTIF($A$2:A34,A34)=1,1,0) -> 1
A35: 1424 | B35: 44328 | C35: BMW 3 Series | D35: 2020 | E35: 9248 | F35: 12000 | G35: =IF(OR(F35="",E35=""),"",F35-E35) -> 2752 | H35: 120000 | I35: Diesel | J35: Automatic | K35: Private | L35: Europe | M35: Blue | N35: 3 | O35: =IF(E35<1000,"Outlier","Normal") -> Normal | P35: =IF(COUNTIF($A$2:$A$2501,A35)>1,"Duplicate ID","Unique ID") -> Duplicate ID | Q35: =IF(E35<5000,"0-4,999",IF(E35<10000,"5,000-9,999",IF(E35<15000,"10,000-14,999",IF(E35<20000,"15,000-19,999",IF(E35<25000,"20,000-24,999","25,000-30,000"))))) -> 5,000-9,999 | R35: =IF(COUNTIF($A$2:A35,A35)=1,1,0) -> 1
A36: 1559 | B36: 45299 | C36: Toyota Corolla | D36: 2019 | E36: 13568 | F36: 18000 | G36: =IF(OR(F36="",E36=""),"",F36-E36) -> 4432 | H36: 60000 | I36: Hybrid | J36: Automatic | K36: Private | L36: Europe | M36: Blue | N36: 2 | O36: =IF(E36<1000,"Outlier","Normal") -> Normal | P36: =IF(COUNTIF($A$2:$A$2501,A36)>1,"Duplicate ID","Unique ID") -> Duplicate ID | Q36: =IF(E36<5000,"0-4,999",IF(E36<10000,"5,000-9,999",IF(E36<15000,"10,000-14,999",IF(E36<20000,"15,000-19,999",IF(E36<25000,"20,000-24,999","25,000-30,000"))))) -> 10,000-14,999 | R36: =IF(COUNTIF($A$2:A36,A36)=1,1,0) -> 1
A37: 1027 | B37: 45290 | C37: Volkswagen Golf | D37: 2016 | E37: 24903 | F37: 31000 | G37: =IF(OR(F37="",E37=""),"",F37-E37) -> 6097 | H37: 25000 | I37: Petrol | J37: Automatic | K37: Dealer | L37: South America | M37: White | N37: 0 | O37: =IF(E37<1000,"Outlier","Normal") -> Normal | P37: =IF(COUNTIF($A$2:$A$2501,A37)>1,"Duplicate ID","Unique ID") -> Unique ID | Q37: =IF(E37<5000,"0-4,999",IF(E37<10000,"5,000-9,999",IF(E37<15000,"10,000-14,999",IF(E37<20000,"15,000-19,999",IF(E37<25000,"20,000-24,999","25,000-30,000"))))) -> 20,000-24,999 | R37: =IF(COUNTIF($A$2:A37,A37)=1,1,0) -> 1
A38: 1345 | B38: 44866 | C38: BMW 3 Series | D38: 2020 | E38: 17276 | F38: 22000 | G38: =IF(OR(F38="",E38=""),"",F38-E38) -> 4724 | H38: 25000 | I38: Electric | J38: Automatic | K38: Dealer | L38: South America | M38: Black | N38: Unknown | O38: =IF(E38<1000,"Outlier","Normal") -> Normal | P38: =IF(COUNTIF($A$2:$A$2501,A38)>1,"Duplicate ID","Unique ID") -> Duplicate ID | Q38: =IF(E38<5000,"0-4,999",IF(E38<10000,"5,000-9,999",IF(E38<15000,"10,000-14,999",IF(E38<20000,"15,000-19,999",IF(E38<25000,"20,000-24,999","25,000-30,000"))))) -> 15,000-19,999 | R38: =IF(COUNTIF($A$2:A38,A38)=1,1,0) -> 1
A39: 1031 | B39: 44279 | C39: Toyota Corolla | D39: 2019 | E39: 13438 | F39: 15000 | G39: =IF(OR(F39="",E39=""),"",F39-E39) -> 1562 | H39: 120000 | I39: Diesel | J39: Manual | K39: Dealer | L39: South America | M39: Black | N39: Unknown | O39: =IF(E39<1000,"Outlier","Normal") -> Normal | P39: =IF(COUNTIF($A$2:$A$2501,A39)>1,"Duplicate ID","Unique ID") -> Duplicate ID | Q39: =IF(E39<5000,"0-4,999",IF(E39<10000,"5,000-9,999",IF(E39<15000,"10,000-14,999",IF(E39<20000,"15,000-19,999",IF(E39<25000,"20,000-24,999","25,000-30,000"))))) -> 10,000-14,999 | R39: =IF(COUNTIF($A$2:A39,A39)=1,1,0) -> 1
A40: 1167 | B40: 44431 | C40: Ford Focus | D40: 2021 | E40: 15626 | F40: 18000 | G40: =IF(OR(F40="",E40=""),"",F40-E40) -> 2374 | H40: 40000 | I40: Hybrid | J40: Unknown | K40: Private | L40: South America | M40: White | N40: 0 | O40: =IF(E40<1000,"Outlier","Normal") -> Normal | P40: =IF(COUNTIF($A$2:$A$2501,A40)>1,"Duplicate ID","Unique ID") -> Duplicate ID | Q40: =IF(E40<5000,"0-4,999",IF(E40<10000,"5,000-9,999",IF(E40<15000,"10,000-14,999",IF(E40<20000,"15,000-19,999",IF(E40<25000,"20,000-24,999","25,000-30,000"))))) -> 15,000-19,999 | R40: =IF(COUNTIF($A$2:A40,A40)=1,1,0) -> 1
...

Sheet 3_Pivot
A1: Summary Tables
A3: Selling Price Distribution | D3: Average Selling Price by Fuel Type | G3: Average Selling Price by Car Model | J3: Count of Cars by Region
A4: Price_Range | B4: Count | D4: Fuel_Type | E4: Avg_Selling_Price | G4: Car_Model | H4: Avg_Selling_Price | J4: Region | K4: Count
A5: 0-4,999 | B5: =COUNTIF(CleanData[Price_Range],A5) -> 430 | D5: Diesel | E5: =IFERROR(AVERAGEIF(CleanData[Fuel_Type],D5,CleanData[Selling_Price]),0) -> 12874.443 | G5: Audi A4 | H5: =IFERROR(AVERAGEIF(CleanData[Car_Model],G5,CleanData[Selling_Price]),0) -> 14287.551 | J5: Asia | K5: =COUNTIF(CleanData[Region],J5) -> 551
A6: 5,000-9,999 | B6: =COUNTIF(CleanData[Price_Range],A6) -> 579 | D6: Electric | E6: =IFERROR(AVERAGEIF(CleanData[Fuel_Type],D6,CleanData[Selling_Price]),0) -> 13768.788 | G6: BMW 3 Series | H6: =IFERROR(AVERAGEIF(CleanData[Car_Model],G6,CleanData[Selling_Price]),0) -> 13054.642 | J6: Europe | K6: =COUNTIF(CleanData[Region],J6) -> 559
A7: 10,000-14,999 | B7: =COUNTIF(CleanData[Price_Range],A7) -> 461 | D7: Hybrid | E7: =IFERROR(AVERAGEIF(CleanData[Fuel_Type],D7,CleanData[Selling_Price]),0) -> 13711.239 | G7: Ford Focus | H7: =IFERROR(AVERAGEIF(CleanData[Car_Model],G7,CleanData[Selling_Price]),0) -> 13074.45 | J7: North America | K7: =COUNTIF(CleanData[Region],J7) -> 549
A8: 15,000-19,999 | B8: =COUNTIF(CleanData[Price_Range],A8) -> 427 | D8: Petrol | E8: =IFERROR(AVERAGEIF(CleanData[Fuel_Type],D8,CleanData[Selling_Price]),0) -> 13302.504 | G8: Honda Civic | H8: =IFERROR(AVERAGEIF(CleanData[Car_Model],G8,CleanData[Selling_Price]),0) -> 13205.453 | J8: South America | K8: =COUNTIF(CleanData[Region],J8) -> 570
A9: 20,000-24,999 | B9: =COUNTIF(CleanData[Price_Range],A9) -> 345 | D9: Unknown | E9: =IFERROR(AVERAGEIF(CleanData[Fuel_Type],D9,CleanData[Selling_Price]),0) -> 13259.554 | G9: Mercedes C-Class | H9: =IFERROR(AVERAGEIF(CleanData[Car_Model],G9,CleanData[Selling_Price]),0) -> 12959.494 | J9: Unknown | K9: =COUNTIF(CleanData[Region],J9) -> 271
A10: 25,000-30,000 | B10: =COUNTIF(CleanData[Price_Range],A10) -> 258 | G10: Toyota Corolla | H10: =IFERROR(AVERAGEIF(CleanData[Car_Model],G10,CleanData[Selling_Price]),0) -> 13550.837
G11: Volkswagen Golf | H11: =IFERROR(AVERAGEIF(CleanData[Car_Model],G11,CleanData[Selling_Price]),0) -> 13548.279

Sheet 4_Charts
A1: Dashboard Charts
